<?xml version="1.0"?>
<robot xmlns:xacro="http://www.ros.org/wiki/xacro">
	
	<material name="blue">
         	<color rgba="0 0 0.8 1"/>
      	</material>

	<material name="white">
         	<color rgba="1 1 1 1"/>
      	</material>

    	<material name="orange">
        	<color rgba="1 0.3 0.1 1"/>
    	</material>
    
    	<material name="black">
        	<color rgba="0 0 0 1"/>
    	</material>
    	
    	<link name="base_footprint">
    		<origin xyz="0.0 0.0 0.0"/>
    	</link>
    	       
       <joint name="base_footprint_joint" type="fixed">
       	<origin xyz="0 0 0" rpy="0 0 0"/>
        	<parent link="base_footprint"/>
        	<child link="base_link"/>
        	
    	</joint>
        	
       <link name="base_link">
       	<origin xyz="0.0 0.0 0.0"/>
       
       </link>



       
    <!-- CHASSIS_LINK -->

    <joint name="chassis_joint" type="fixed">
        <parent link="base_link"/>
        <child link="chassis"/>
        <origin xyz="-0.1 0.0 0.0"/>
    </joint>

    <link name="chassis">
        <inertial>
            <origin xyz="0.2 0.0 0.17" rpy="0.0 0.0 0.0"/>
            <mass value="12.0"/>
            <inertia ixx="0.1" ixy="0.0" ixz="0.0" iyy="0.1" iyz="0.0" izz="0.1"/>
        </inertial>
        <visual>
            <origin xyz="0.2 0.0 0.17" rpy="0.0 0.0 0.0"/>
            <geometry>
                <box size="0.4 0.4 0.2"/>
            </geometry>
            <material name="orange"/>
        </visual>
        <collision>
            <origin xyz="0.2 0.0 0.17" rpy="0.0 0.0 0.0"/>
            <geometry>
                <box size="0.4 0.4 0.2"/>
            </geometry>
        </collision>
    </link>
       
       

<!--right wheel-->
       
       <link name="right_wheel">
         	<visual>
           		<geometry>
             			<cylinder length="0.04" radius="0.07"/>
           		</geometry>
           		<material name="blue"/>
         	</visual>
         	<collision>
           		<geometry>
             			<cylinder length="0.04" radius="0.07"/>
           		</geometry>
         	</collision>
       	<inertial>
            		<mass value="0.5" />
            		<inertia ixx="0.1" ixy="0.0" ixz="0.0"
                    		iyy="0.1" iyz="0.0"
                    		izz="0.1" />
        	</inertial>
       </link>
       <joint name="right_wheel_joint" type="continuous">
         	<parent link="base_link"/>
         	<child link="right_wheel"/>
         	<origin xyz="0 -0.22 0.07" rpy="${pi/2} 0 0"/>
         	<axis xyz="0 0 -1"/>
       </joint>

	
<!--left wheel-->

	<link name="left_wheel">
         	<visual>
           		<geometry>
             			<cylinder length="0.04" radius="0.07"/>
           		</geometry>
           		<material name="blue"/>
         	</visual>
         	<collision>
           		<geometry>
             			<cylinder length="0.04" radius="0.07"/>
           		</geometry>
         	</collision>
         	<inertial>
            		<mass value="0.5" />
            		<inertia ixx="0.1" ixy="0.0" ixz="0.0"
                    		iyy="0.1" iyz="0.0"
                    		izz="0.1" />
        	</inertial>
       </link>  
       <joint name="left_wheel_joint" type="continuous">
       	<parent link="base_link"/>
         	<child link="left_wheel"/>
         	<origin xyz="0 0.22 0.07" rpy="${-pi/2} 0.0 0.0"/>
         	<axis xyz="0 0 1"/>
       </joint>
       
        
       
<!--caster wheel-->
	<joint name = "caster_wheel_joint" type = "fixed" >
		<parent link = "chassis" />
		<child link = "caster_wheel" />
		<origin xyz = "0.3 0 0.07" />
	</joint>
	
	<link name = "caster_wheel" >
		<visual> 
			<geometry>
				<sphere radius = "0.07" />
			</geometry>
			<material name = "blue" />
		</visual>
		<collision> 
			<geometry>
				<sphere radius = "0.07" />
			</geometry>
		</collision>
		<inertial>
            		<mass value="0.2" />
            		<origin xyz="0 0 0.07" rpy="0 0 0"/>
            		<inertia ixx="0.1" ixy="0.0" ixz="0.0"
                    		iyy="0.1" iyz="0.0"
                    		izz="0.1" />
        	</inertial>
	</link>
	
	
	
       <!-- lidar -->
    <joint name="joint_scan" type="fixed">
        <origin xyz="0.0 0.0 0.53" rpy="0.0 0.0 0.0"/>     <!--0.215 = 0.2 + 0.03/2-->
        <parent link="base_link"/>
        <!-- <child link="base_scan"/> -->
        <child link="laser"/>
    </joint>

    <!-- <link name="base_scan"> -->
    <link name="laser">
        <visual>
            <geometry>
                <cylinder radius="0.04" length="0.04"/>
            </geometry>
            <material name="black"/>
        </visual>
        <collision>
            <geometry>
                <cylinder radius="0.04" length="0.04"/>
            </geometry>
        </collision>
        <inertial>
            <mass value="0.2"/>
            <inertia ixx="0.01" ixy="0.0" ixz="0.0" iyy="0.01" iyz="0.0" izz="0.01"/>
        </inertial>
    </link>


    <!-- plugin lidar -->

    
</robot>

